<!DOCTYPE html>
<html>
<head>
<meta charset="ISO-8859-1">
<title>Promise对象</title>
<script type="text/javascript">
//1Promise的含义
//Promise是异步编程的一种解决方案,比传统的解决方案——回调函数和事件——更合理和更强大
//Promise对象有以下2个特点
//(1)对象的状态不受外界影响：Pending（进行中）、Resolved（已完成，又称Fulfilled）和Rejected（已失败）。
//只有异步操作的结果，可以决定当前是哪一种状态，任何其他操作都无法改变这个状态
//(2)一旦状态改变,就不会在变,任何时候都可以得到这个结果
//Promise对象的状态改变，只有两种可能：从Pending变为Resolved和从Pending变为Rejected。
//只要这两种情况发生，状态就凝固了，不会再变了，会一直保持这个结果
//有了Promise对象，就可以将异步操作以同步操作的流程表达出来,避免了层层嵌套的回调函数

//Promise的缺点:(1)无法取消Promise,(2)如果不设置回调函数,Promise内部抛出的错误,不会反应到外部
//(3)当处于Pending状态时,无法得知目前进展到哪一个阶段（刚刚开始还是即将完成）。
//如果某些事件不断地反复发生，一般来说，使用stream模式是比部署Promise更好的选择

//2基本用法
//下面代码创造了一个Promise实例
var promise = new Promise(function(resolve,reject){
	//...some code
	if(/*异步操作成功*/){
		resolve(value);
	}else{
		reject(error);
	}
});
//Promise构造函数接受一个函数作为参数，该函数的两个参数分别是resolve和reject。
//它们是两个函数，由JavaScript引擎提供，不用自己部署

//resolve函数的作用是，将Promise对象的状态从“未完成”变为“成功”（即从Pending变为Resolved），在异步操作成功时调用，
//并将异步操作的结果，作为参数传递出去；reject函数的作用是，将Promise对象的状态从“未完成”变为“失败”（即从Pending变为Rejected），
//在异步操作失败时调用，并将异步操作报出的错误，作为参数传递出去

//Promise实例生成以后，可以用then方法分别指定Resolved状态和Reject状态的回调函数
promise.then(function(value){
	//success
},function(reason){
	//failure
});

//下面是一个Promise对象的简单例子
function timeout(ms){
	return new Promise((resolve,reject)=> {
		setTimeout(resolve,ms,"done");
	});
}
timeout(100).then((value)=>{
	console.log(value);
});
//Promise新建后就会立即执行
let promise = new Promise(function(resolve,reject){
	console.log("Promise");
	resolve();
});
promise.then(function(){
	console.log("Resolved");
});
console.log("Hi");
//Promise
//Hi!
//Resolved
//上面代码中，Promise新建后立即执行，所以首先输出的是“Promise”。然后，then方法指定的回调函数，
//将在当前脚本所有同步任务执行完才会执行，所以“Resolved”最后输出

//下面是异步加载图片的例子
function loadImageAsync(url){
	return new Promise(function(resolve,reject){
		var image = new Image();
		image.onload = function(){
			resolve(image);
		};
		image.onerror = function(){
			reject(new Error('Could not load image at ' + url));
		};
		image.src = url;
	});
}
//下面是一个用Promise对象实现的Ajax操作的例子
var getJSON = function(url){
	var promise = new Promise(function(resolve,reject){
		var client = new XMLHttpRequest();
		client.open("GET",url);
		client.onreadystatechange = handler;
		client.responseTyep = "json";
		client.setRequestHeader("Accept",'application/json');
		client.send();
		
		function handler(){
			if(this.readyState !== 4){
			   return;
			}
			if(this.status === 200){
				resolve(this.response);
			}else{
				reject(new Error(this.statusText));
			}
		}
	});
	
	return promise;
};

getJSON("/posts.json").then(function(json){
	console.log("contents:" + json)
},function(error){
	console.log("error:" + error);
});

//resolve函数的参数除了正常的值以外，还可能是另一个Promise实例，表示异步操作的结果有可能是一个值，也有可能是另一个异步操作
var p1 = new Promise(function(resolve,reject){
	//...
});

var p2 = new Promise(function(resolve,reject){
	resolve(p1);//一个异步操作的结果是返回另一个异步操作
});
//注意，这时p1的状态就会传递给p2，也就是说，p1的状态决定了p2的状态。如果p1的状态是Pending，那么p2的回调函数就会等待p1的状态改变；
//如果p1的状态已经是Resolved或者Rejected，那么p2的回调函数将会立刻执行
var p1 = new Promise(function(resolve,reject){
	setTimeout(()=> reject(new Error("fail")),3000);
});
var p2 = new Promise(function(resolve,reject){
	setTimeout(()=> resolve(p1),1000);
});

p.then(result => console.log(result)).catch(error => console.log(error));//Error: fail

//3Promise.prototype.then()
getJSON("/posts.json").then(function(json){
	return json.post;
}).then(function(post){
	//...
});
//采用链式的then，可以指定一组按照次序调用的回调函数。这时，前一个回调函数，
//有可能返回的还是一个Promise对象（即有异步操作），这时后一个回调函数，就会等待该Promise对象的状态发生变化，才会被调用
getJSON("/post/1.json").then(function(post){
	return getJSON(post.commentURL);
}).then(function funcA(comments){
	console.log("Resolved:",comments);
},function funcB(err){
	console.log("Rejected:",err);
});
//上面代码中，第一个then方法指定的回调函数，返回的是另一个Promise对象。这时，第二个then方法指定的回调函数，
//就会等待这个新的Promise对象状态发生变化。如果变为Resolved，就调用funcA，如果状态变为Rejected，就调用funcB
getJSON("/post/1.json").then(
		post => getJSON(post.commentURL);
).then(comments => console.log("Resolved:",comments),
       err =>  console.log("Rejected:",err)
);

//4Promise.prototype.catch()
//Promise.prototype.catch方法是.then(null, rejection)的别名，用于指定发生错误时的回调函数
getJSON("/posts.json").then(function(posts){
	//...
}).catch(function(error){
	// 处理 getJSON 和 前一个回调函数运行时发生的错误
	console.log("发送错误!",error);
});

p.then((val) => console.log("fulfilled:",value))
.catch((err) => console.log("rejected:",err));
//等同于
p.then((val) => console.log("fulfilled:",val))
.then(null,(err) => console.log("rejected:",err));

//下面是一个例子
var promise = new Promise(function(resolve,reject){
	throw new Error("test");
});
promise.catch(function(error){
	console.log(error);
});
//// 写法一
var promise = new Promise(function(resolve,reject){
	try{
		throw new Error('test');
	}catch(e){
		reject(e);
	}
});
promise.catch(function(error){
	console.log(error);
});
//// 写法二
var promise = new Promise(function(resolve,reject){
	reject(new Error("test")); 
});
promise.catch(function(error){
	console.log(error);
});
//如果Promise状态已经变成Resolved，再抛出错误是无效的
var promise = new Promise(function(resolve,reject){
	resolve("ok");
	throw new Error('test');
});
promise.then(function(value){
	console.log(value);
}).catch(function(error){
	console.log(error);
});
//Promise对象的错误具有“冒泡”性质，会一直向后传递，直到被捕获为止。也就是说，错误总是会被下一个catch语句捕获
getJSON("/post/1.json").then(function(post){
	return getJSON(post.commentURL);
}).then(function(comments){
	//some code
}).catch(function(error){
	//处理前面3个promise产生的错误
})
//一般来说，不要在then方法里面定义Reject状态的回调函数（即then的第二个参数），总是使用catch方法。
//bad
promise.then(function(data){
	//success
},function(err){
	//error
});
//goog
promise.then(function(data){
	//success
}).catch(function(err){
	//error
});
//跟传统的try/catch代码块不同的是，如果没有使用catch方法指定错误处理的回调函数，
//Promise对象抛出的错误不会传递到外层代码，即不会有任何反应
var someAsyncThing = function(){
	return new Promise(function(resolve,reject){
		//下面一行会报错，因为x没有声明
		resolve(x+2);
	});
};
someAsyncThing().then(function(){
	console.log('everything is great');
});

var promise = new Promise(function(resolve,reject){
	resolve("ok");
	setTimeout(function(){
		throw new Error("test")
	},0);
});
promise.then(function(value){
	console.log(value);
});
//Node 有一个unhandledRejection事件，专门监听未捕获的reject错误。
process.on("unhandledRejection",function(err,p){
	console.error(err.stack);
});
//需要注意的是，catch方法返回的还是一个 Promise 对象，因此后面还可以接着调用then方法
var someAsyncThing = function(){
	return new Promise(function(resolve,reject){
		//下面一行会报错，因为x没有声明
		resolve(x + 2);
	});
};
someAsyncThing().catch(function(err){
	console.log("oh no", error);
}).then(function(){
	console.log('carry on');
});
//上面代码运行完catch方法指定的回调函数，会接着运行后面那个then方法指定的回调函数。如果没有报错，则会跳过catch方法
Promise.resolve().catch(function(error){
	console.log("oh no ",error);
}).then(function(){
	console.log("carry on");
});
//catch方法之中，还能再抛出错误。
var someAsyncThing = function() {
  return new Promise(function(resolve, reject) {
    // 下面一行会报错，因为x没有声明
    resolve(x + 2);
  });
};
someAsyncThing().then(function(){
	return someAsyncThing();
}).catch(function(error){
	console.log('oh no', error);
	// 下面一行会报错，因为y没有声明
	y + 2;
}).then(function(){
	console.log('carry on');
});
//如果改写一下，结果就不一样了
someAsyncThing().then(function(){
	return someAsyncThing();
}).catch(function(error){
	console.log('oh no', error);
	// 下面一行会报错，因为y没有声明
	y + 2;
}).catch(function(){
	console.log('carry on',error);
});
//上面代码中，第二个catch方法用来捕获，前一个catch方法抛出的错误。
//5Promise.all()
//Promise.all方法用于将多个Promise实例，包装成一个新的Promise实例。
var p = Promise.all([p1,p2,p3]);
//生成一个Promise对象的数组
var promises = [2,3,5,7,11,13].map(function(id){
	return getJSON("/post/" + id + ".json");
});
Promise.all(promises).then(function(posts){
	//...
}).catch(function(reason){
	//...
});
//下面是另一个例子。
const databasePromise = connectDatabase();
const booksPromise = databasePromise.then(findAllBooks);
const userPromise = databasePromise.then(getCurrentUser);
Promise.all([booksPromise,userPromise]).then(([books,user]) => pickTopRecommentation(book));

//6Promise.race()
var p = new Promise([p1,p2,p3]);
//下面是一个例子，如果指定时间内没有获得结果，就将Promise的状态变为reject，否则变为resolve
var p = Promise.race([
    fetch('/resource-that-may-take-a-while'),
    new Promise(function(resolve,reject){
    	setTimeout(() => reject(new Error('request timeout')),5000);
    })
]);
p.then(response => console.log(response));
p.catch(error => console.log(error));

//7Promise.resolve()
//有时需要将现有对象转为Promise对象，Promise.resolve方法就起到这个作用
var jsPromise = Promise.resolve($.ajax('/whatever.json'));
//上面代码将jQuery生成的deferred对象，转为一个新的Promise对象
//Promise.resolve等价于下面的写法
Promise.resolve("foo");
//等价于
new Promise(resolve => resolve("foo"));

//8Promise.reject()
var p = Promise.reject('出错了');
//等同于
var p = new Promise((resolve,reject) => reject("出错了"));
p.then(null,function(s){
	console.log(s);
});

const thenable = {
		then(resolve,reject){
			reject("出错了");
		}
};
Promise.reject(thenable).catch(e => {
	console.log(e === thenable);
});

//9两个有用的附加方法
//done
//asyncFunc().then(f1).catch(r1).then(f2).done();
Promise.prototype.done = function(onFulfilled,onRejected){
	this.then(onFulfilled,onRejected).catch(function(reason){
		//抛出一个全局错误
		setTimeout(() => { throw reason},0);
	});
}
//finally
//下面是一个例子，服务器使用Promise处理请求，然后使用finally方法关掉服务器。
/* server.listen(0).then(function(){
	//run test
}).finally(server.stop); */
Promise.prototype.finally = function(callback){
	let P = this.constructor;
	return this.then(
       value => P.resolve(callback()).then(() => value),
       reason => P.resolve(callback()).then() => {throw reason})
	);
};

//10应用
//1加载图片
const preloadImage = function(path){
	return new Promise(function(resolve,reject){
		var img = new Image();
		img.onload = resolve;
		img.onerror = reject;
		img.src = path;
	});
};
//2Generator函数与Promise的结合
function getFoo(){
	return new Promise(function(resolve,reject){
		resolve("foo");
	});
}
var g = function* (){
	try{
		var foo = yield getFoo();
		console.log(foo);
	}catch(e){
		console.log(e);
	}
};

function run(generator){
	var it = generator();
	function go(result){
		if(result.done){
			return result.value;
		}
		return result.value.then(function(value){
			return go(it.next(value));
		},function(error){
			return go(it.throw(error));
		});
	}
	go(it.next());
}
run(g);

//11Promise.try()
const f = () => console.log("now");
Promise.resolve().then(f);
console.log("next");

const f = () => console.log("now");
(async () => f())();
console.log('next');
//需要注意的是，async () => f()会吃掉f()抛出的错误。所以，如果想捕获错误，要使用promise.catch方法
//(async () => f())().then(...).catch(...);

const f = () => console.log('now');
(
  () => new Promise(){
	  resolve => resolve(f())
  }
)();
console.log('next');

function getUsername(userId){
	return database.users.get({id:userId}).then(function(user){
		return user.name;
	});
}
//http://es6.ruanyifeng.com/#docs/promise
//https://developer.mozilla.org/en/docs/Web/JavaScript/Reference/Global_Objects/Promise

</script>
</head>
<body>
</body>
</html>
